<?xml version="1.0"?>
<robot xmlns:xacro="http://ros.org/wiki/xacro" name="robot">




<!-- Parameters -->
  <xacro:property name="wheel_radius" value="0.04"/>
  <xacro:property name="wheel_width" value="0.04"/>
  <xacro:property name="base_length" value="0.30"/>
  <xacro:property name="base_width" value="0.25"/>
  <xacro:property name="base_height" value="0.02"/>
  <xacro:property name="second_base_length" value="0.25"/>
  <xacro:property name="second_base_width" value="0.22"/>
  <xacro:property name="second_base_height" value="0.10"/>
  <xacro:property name="third_base_length" value="0.25"/>
  <xacro:property name="third_base_width" value="0.22"/>
  <xacro:property name="third_base_height" value="0.065"/>
  <xacro:property name="lidar_radius" value="0.035"/>
  <xacro:property name="lidar_height" value="0.045"/>

   <gazebo>
    <plugin name="gazebo_ros_control" filename="libgazebo_ros_control.so"/>
  </gazebo>

  <link name="world"></link>




<!-- motor bolck -->
  <link name="base_link">
  <inertial>
      <mass value="5.0"/>
      <origin xyz="0 0 0"/>
      <inertia ixx="0.01" ixy="0.0" ixz="0.0" iyy="0.01" iyz="0.0" izz="0.01"/>
    </inertial>
    <visual>
      <geometry>
        <box size="0.21 0.145 0.05"/>
      </geometry>
      <origin xyz="0 0 0"/>
      <material name="grey">
        <color rgba="0.5 0.5 0.5 1"/>
      </material>
    </visual>
  </link>

  <joint name="base_link_joint" type="fixed">
    <parent link="world"/>
    <child link="base_link"/>
    <origin xyz="0 0 0"/>
  </joint>

<!-- first_base Link -->
  <link name="first_base">
    <visual>
      <geometry>
        <box size="${base_length} ${base_width} ${base_height}"/>
      </geometry>
      <origin xyz="0 0 0.035"/>
      <material name="silver">
        <color rgba="0.7 0.7 0.7 1"/>
      </material>
    </visual>
  </link>

  <joint name="first_base_joint" type="fixed">
    <parent link="base_link"/>
    <child link="first_base"/>
    <origin xyz="0 0 0" rpy="0 0 0"/>
   </joint>



<!-- Second Base -->
  <link name="second_base">
    <visual>
      <geometry>
        <box size="${second_base_length} ${second_base_width} ${second_base_height}"/>
      </geometry>
      <origin xyz="0 0 0.095"/>
      <material name="grey">
        <color rgba="0.5 0.5 0.5 1"/>
      </material>
    </visual>
  </link>

  <joint name="second_base_joint" type="fixed">
    <parent link="first_base"/>
    <child link="second_base"/>
    <origin xyz="0 0 0"/>
  </joint>



<!-- Third Base -->
  <link name="third_base">
    <visual>
      <geometry>
        <box size="${third_base_length} ${third_base_width} ${third_base_height}"/>
      </geometry>
      <origin xyz="0 0 0.17"/>
      <material name="dark_grey">
        <color rgba="0.3 0.3 0.3 1"/>
      </material>
    </visual>
  </link>

  <joint name="third_base_joint" type="fixed">
    <parent link="second_base"/>
    <child link="third_base"/>
    <origin xyz="0 0 0"/>
  </joint>

<!-- Lidar -->
  <link name="lidar">
    <visual>
      <geometry>
        <cylinder length="${lidar_height}" radius="${lidar_radius}"/>
      </geometry>
      <origin xyz="0 0 0.16"/>
      <material name="black">
        <color rgba="0 0 0 1"/>
      </material>
    </visual>
  </link>

  <joint name="lidar_joint" type="fixed">
    <parent link="third_base"/>
    <child link="lidar"/>
    <origin xyz="0 0 ${third_base_height}"/>
  </joint>

<!-- Pan Servo -->
  <link name="pan_servo">
    <visual>
      <geometry>
        <box size="0.07 0.18 0.12"/>
      </geometry>
      <origin xyz="0.08 0 0.04"/>
      <material name="orange">
        <color rgba="1 0.5 0 1"/>
      </material>
    </visual>
  </link>

  <joint name="pan_joint" type="fixed">
    <parent link="base_link"/>
    <child link="pan_servo"/>
    <origin xyz="0.1 0 ${third_base_height}"/>
    <axis xyz="0 0 1"/>
    <limit effort="1" velocity="1" lower="-3.1416" upper="3.1416"/>
  </joint>



<!-- Tilt Servo 
  <link name="tilt_servo">
    <visual>
      <geometry>
        <box size="0.04 0.04 0.04"/>
      </geometry>
      <origin xyz="0 0 0.05"/>
      <material name="blue">
        <color rgba="0 0 1 1"/>
      </material>
    </visual>
  </link>

  <joint name="tilt_joint" type="continuous">
    <parent link="pan_servo"/>
    <child link="tilt_servo"/>
    <origin xyz="0 0 0.05"/>
    <axis xyz="1 0 0"/>
    <limit effort="1" velocity="1" lower="-3.1416" upper="3.1416"/>
  </joint>
-->

<!--Wheels-->
  <!-- This is the back right wheel of the robot -->
   <joint name="wheel1_joint" type="continuous" >
        <parent link="base_link"/>
        <child  link="wheel1_link" />
        <origin xyz="-0.09 -0.09 -0.02" rpy="0 0 0" />
        <axis xyz="0 1 0"/>   
    </joint>
    <link name="wheel1_link">
        <visual>
            <origin rpy="1.570795 0 0" xyz="0 0 0"/>
            <geometry>
                <cylinder length="0.035" radius="0.04"/>
            </geometry>
             
            <material name="yellow">
                <color rgba="1 1 0 1"/>
            </material>
        </visual>
    </link>
     
     
    <!-- This is the back left wheel of the robot -->
    <joint name="wheel2_joint" type="continuous" >
        <parent link="base_link"/>
        <child  link="wheel2_link" />
        <origin xyz="-0.09 0.09 -0.02" rpy="0 0 0" />
        <axis xyz="0 1 0"/>   
    </joint>
    <link name="wheel2_link">
        <visual>
            <origin rpy="1.570795 0 0" xyz="0 0 0"/>
            <geometry>
                <cylinder length="0.035" radius="0.04"/>
            </geometry>
             
            <material name="yellow">
                <color rgba="1 1 0 1"/>
            </material>
        </visual>
    </link>
     
     
     
    <!-- This is the front right wheel of the robot -->
    <joint name="wheel3_joint" type="continuous" >
        <parent link="base_link"/>
        <child  link="wheel3_link" />
        <origin xyz="0.075 -0.09 -0.02" rpy="0 0 0" />
        <axis xyz="0 1 0"/>   
    </joint>
    <link name="wheel3_link">
        <visual>
            <origin rpy="1.570795 0 0" xyz="0 0 0"/>
            <geometry>
                <cylinder length="0.035" radius="0.04"/>
            </geometry>
             
            <material name="yellow">
                <color rgba="1 1 0 1"/>
            </material>
        </visual>
    </link>
     
     
     
    <!-- This is the front left wheel of the robot -->
    <joint name="wheel4_joint" type="continuous" >
        <parent link="base_link"/>
        <child  link="wheel4_link" />
        <origin xyz="0.075 0.09 -0.02" rpy="0 0 0" />
        <axis xyz="0 1 0"/>   
    </joint>
    <link name="wheel4_link">
        <visual>
            <origin rpy="1.570795 0 0" xyz="0 0 0"/>
            <geometry>
                <cylinder length="0.035" radius="0.04"/>
            </geometry>
             
            <material name="yellow">
                <color rgba="1 1 0 1"/>
            </material>
        </visual>
    </link>

</robot>
