<?xml version="1.0" ?>
<!-- =================================================================================== -->
<!-- |    This document was autogenerated by xacro from robot.xacro                    | -->
<!-- |    EDITING THIS FILE BY HAND IS NOT RECOMMENDED                                 | -->
<!-- =================================================================================== -->
<robot name="robot">
  <!---->
  <link name="world"/>
  <!-- motor bolck -->
  <link name="motor_bolck">
    <visual>
      <geometry>
        <box size="0.21 0.145 0.05"/>
      </geometry>
      <origin xyz="0 0 0"/>
      <material name="grey">
        <color rgba="0.5 0.5 0.5 1"/>
      </material>
    </visual>
  </link>
  <!--
  <joint name="motor_joint" type="fixed">
    <parent link="world"/>
    <child link="base_link"/>
    <origin xyz="0 0 0.02"/>
  </joint>
-->
  <!-- Base Link -->
  <link name="base_link">
    <visual>
      <geometry>
        <box size="0.3 0.25 0.02"/>
      </geometry>
      <origin xyz="0 0 0.035"/>
      <material name="silver">
        <color rgba="0.7 0.7 0.7 1"/>
      </material>
    </visual>
  </link>
  <joint name="base_joint" type="fixed">
    <parent link="motor_bolck"/>
    <child link="base_link"/>
    <origin rpy="0 0 0" xyz="0 0 0"/>
  </joint>
  <!-- Second Base -->
  <link name="second_base">
    <visual>
      <geometry>
        <box size="0.25 0.22 0.1"/>
      </geometry>
      <origin xyz="0 0 0.095"/>
      <material name="grey">
        <color rgba="0.5 0.5 0.5 1"/>
      </material>
    </visual>
  </link>
  <joint name="second_base_joint" type="fixed">
    <parent link="base_link"/>
    <child link="second_base"/>
    <origin xyz="0 0 0"/>
  </joint>
  <!-- Third Base -->
  <link name="third_base">
    <visual>
      <geometry>
        <box size="0.25 0.22 0.065"/>
      </geometry>
      <origin xyz="0 0 0.17"/>
      <material name="dark_grey">
        <color rgba="0.3 0.3 0.3 1"/>
      </material>
    </visual>
  </link>
  <joint name="third_base_joint" type="fixed">
    <parent link="second_base"/>
    <child link="third_base"/>
    <origin xyz="0 0 0"/>
  </joint>
  <!-- Lidar -->
  <link name="lidar">
    <visual>
      <geometry>
        <cylinder length="0.045" radius="0.035"/>
      </geometry>
      <origin xyz="0 0 0.16"/>
      <material name="black">
        <color rgba="0 0 0 1"/>
      </material>
    </visual>
  </link>
  <joint name="lidar_joint" type="fixed">
    <parent link="third_base"/>
    <child link="lidar"/>
    <origin xyz="0 0 0.065"/>
  </joint>
  <!-- Pan Servo -->
  <link name="pan_servo">
    <visual>
      <geometry>
        <box size="0.07 0.18 0.12"/>
      </geometry>
      <origin xyz="0.08 0 0.04"/>
      <material name="orange">
        <color rgba="1 0.5 0 1"/>
      </material>
    </visual>
  </link>
  <joint name="pan_joint" type="fix">
    <parent link="base_link"/>
    <child link="pan_servo"/>
    <origin xyz="0.1 0 0.065"/>
    <axis xyz="0 0 1"/>
    <limit effort="1" lower="-3.1416" upper="3.1416" velocity="1"/>
  </joint>
  <!-- Tilt Servo 
  <link name="tilt_servo">
    <visual>
      <geometry>
        <box size="0.04 0.04 0.04"/>
      </geometry>
      <origin xyz="0 0 0.05"/>
      <material name="blue">
        <color rgba="0 0 1 1"/>
      </material>
    </visual>
  </link>

  <joint name="tilt_joint" type="continuous">
    <parent link="pan_servo"/>
    <child link="tilt_servo"/>
    <origin xyz="0 0 0.05"/>
    <axis xyz="1 0 0"/>
    <limit effort="1" velocity="1" lower="-3.1416" upper="3.1416"/>
  </joint>
-->
  <!--Wheels-->
  <!-- This is the back right wheel of the robot -->
  <joint name="wheel1_joint" type="continuous">
    <parent link="motor_bolck"/>
    <child link="wheel1_link"/>
    <origin rpy="0 0 0" xyz="-0.09 -0.09 -0.02"/>
    <axis xyz="0 1 0"/>
  </joint>
  <link name="wheel1_link">
    <visual>
      <origin rpy="1.570795 0 0" xyz="0 0 0"/>
      <geometry>
        <cylinder length="0.035" radius="0.04"/>
      </geometry>
      <material name="yellow">
        <color rgba="1 1 0 1"/>
      </material>
    </visual>
  </link>
  <!-- This is the back left wheel of the robot -->
  <joint name="wheel2_joint" type="continuous">
    <parent link="motor_bolck"/>
    <child link="wheel2_link"/>
    <origin rpy="0 0 0" xyz="-0.09 0.09 -0.02"/>
    <axis xyz="0 1 0"/>
  </joint>
  <link name="wheel2_link">
    <visual>
      <origin rpy="1.570795 0 0" xyz="0 0 0"/>
      <geometry>
        <cylinder length="0.035" radius="0.04"/>
      </geometry>
      <material name="yellow">
        <color rgba="1 1 0 1"/>
      </material>
    </visual>
  </link>
  <!-- This is the front right wheel of the robot -->
  <joint name="wheel3_joint" type="continuous">
    <parent link="motor_bolck"/>
    <child link="wheel3_link"/>
    <origin rpy="0 0 0" xyz="0.075 -0.09 -0.02"/>
    <axis xyz="0 1 0"/>
  </joint>
  <link name="wheel3_link">
    <visual>
      <origin rpy="1.570795 0 0" xyz="0 0 0"/>
      <geometry>
        <cylinder length="0.035" radius="0.04"/>
      </geometry>
      <material name="yellow">
        <color rgba="1 1 0 1"/>
      </material>
    </visual>
  </link>
  <!-- This is the front left wheel of the robot -->
  <joint name="wheel4_joint" type="continuous">
    <parent link="motor_bolck"/>
    <child link="wheel4_link"/>
    <origin rpy="0 0 0" xyz="0.075 0.09 -0.02"/>
    <axis xyz="0 1 0"/>
  </joint>
  <link name="wheel4_link">
    <visual>
      <origin rpy="1.570795 0 0" xyz="0 0 0"/>
      <geometry>
        <cylinder length="0.035" radius="0.04"/>
      </geometry>
      <material name="yellow">
        <color rgba="1 1 0 1"/>
      </material>
    </visual>
  </link>
</robot>
